<?xml version="1.0"?>
<robot name="minecraft_robot">
  <!-- Material referencing the Minecraft skin texture -->
  <material name="skin">
    <texture filename="skin.png"/>
  </material>

  <!-- Pelvis / Base Link -->
  <link name="base_link">
    <visual>
      <origin xyz="0 0 0" rpy="0 0 0"/>
      <geometry>
        <!-- 0.3m x 0.2m x 0.2m block for pelvis -->
        <box size="0.3 0.2 0.2"/>
      </geometry>
      <material name="skin"/>
    </visual>
    <collision>
      <origin xyz="0 0 0" rpy="0 0 0"/>
      <geometry>
        <box size="0.3 0.2 0.2"/>
      </geometry>
    </collision>
    <inertial>
      <mass value="1.0"/>
      <inertia ixx="0.001" ixy="0.0" ixz="0.0" iyy="0.001" iyz="0.0" izz="0.001"/>
    </inertial>
  </link>

  <!-- Right Leg -->
  <link name="thigh_link_r">
    <visual>
      <origin xyz="0 -0.1 -0.25" rpy="0 0 0"/>
      <geometry>
        <box size="0.1 0.1 0.5"/>
      </geometry>
      <material name="skin"/>
    </visual>
    <collision>
      <origin xyz="0 -0.1 -0.25" rpy="0 0 0"/>
      <geometry><box size="0.1 0.1 0.5"/></geometry>
    </collision>
  </link>
  <joint name="hip_joint_r" type="revolute">
    <parent link="base_link"/>
    <child link="thigh_link_r"/>
    <origin xyz="0 -0.1 0" rpy="0 0 0"/>
    <axis xyz="1 0 0"/>
    <limit lower="-1.57" upper="1.57" effort="10" velocity="1.0"/>
  </joint>

  <link name="shin_link_r">
    <visual>
      <origin xyz="0 -0.1 -0.75" rpy="0 0 0"/>
      <geometry><box size="0.1 0.1 0.5"/></geometry>
      <material name="skin"/>
    </visual>
    <collision>
      <origin xyz="0 -0.1 -0.75" rpy="0 0 0"/>
      <geometry><box size="0.1 0.1 0.5"/></geometry>
    </collision>
  </link>
  <joint name="knee_joint_r" type="revolute">
    <parent link="thigh_link_r"/>
    <child link="shin_link_r"/>
    <origin xyz="0 -0.1 -0.5" rpy="0 0 0"/>
    <axis xyz="1 0 0"/>
    <limit lower="0" upper="2.0" effort="10" velocity="1.0"/>
  </joint>

  <link name="foot_link_r">
    <visual>
      <origin xyz="0 -0.1 -1.0" rpy="0 0 0"/>
      <geometry><box size="0.15 0.1 0.05"/></geometry>
      <material name="skin"/>
    </visual>
    <collision>
      <origin xyz="0 -0.1 -1.0" rpy="0 0 0"/>
      <geometry><box size="0.15 0.1 0.05"/></geometry>
    </collision>
  </link>
  <joint name="ankle_joint_r" type="revolute">
    <parent link="shin_link_r"/>
    <child link="foot_link_r"/>
    <origin xyz="0 -0.1 -1.0" rpy="0 0 0"/>
    <axis xyz="1 0 0"/>
    <limit lower="-0.5" upper="0.5" effort="5" velocity="1.0"/>
  </joint>

  <!-- Left Leg (mirror of right) -->
  <link name="thigh_link_l">
    <visual><origin xyz="0 0.1 -0.25"/><geometry><box size="0.1 0.1 0.5"/></geometry><material name="skin"/></visual>
    <collision><origin xyz="0 0.1 -0.25"/><geometry><box size="0.1 0.1 0.5"/></geometry></collision>
  </link>
  <joint name="hip_joint_l" type="revolute">
    <parent link="base_link"/><child link="thigh_link_l"/><origin xyz="0 0.1 0"/><axis xyz="1 0 0"/><limit lower="-1.57" upper="1.57" effort="10" velocity="1.0"/>
  </joint>

  <link name="shin_link_l">
    <visual><origin xyz="0 0.1 -0.75"/><geometry><box size="0.1 0.1 0.5"/></geometry><material name="skin"/></visual>
    <collision><origin xyz="0 0.1 -0.75"/><geometry><box size="0.1 0.1 0.5"/></geometry></collision>
  </link>
  <joint name="knee_joint_l" type="revolute">
    <parent link="thigh_link_l"/><child link="shin_link_l"/><origin xyz="0 0.1 -0.5"/><axis xyz="1 0 0"/><limit lower="0" upper="2.0" effort="10" velocity="1.0"/>
  </joint>

  <link name="foot_link_l">
    <visual><origin xyz="0 0.1 -1.0"/><geometry><box size="0.15 0.1 0.05"/></geometry><material name="skin"/></visual>
    <collision><origin xyz="0 0.1 -1.0"/><geometry><box size="0.15 0.1 0.05"/></geometry></collision>
  </link>
  <joint name="ankle_joint_l" type="revolute">
    <parent link="shin_link_l"/><child link="foot_link_l"/><origin xyz="0 0.1 -1.0"/><axis xyz="1 0 0"/><limit lower="-0.5" upper="0.5" effort="5" velocity="1.0"/>
  </joint>

  <!-- Torso -->
  <link name="torso_link">
    <visual>
      <origin xyz="0 0 0.6"/>
      <geometry><box size="0.4 0.25 0.6"/></geometry>
      <material name="skin"/>
    </visual>
    <collision><origin xyz="0 0 0.6"/><geometry><box size="0.4 0.25 0.6"/></geometry></collision>
  </link>
  <joint name="chest_joint" type="fixed">
    <parent link="base_link"/><child link="torso_link"/><origin xyz="0 0 0.2"/><axis xyz="0 0 1"/>
  </joint>

  <!-- Head -->
  <link name="head_link">
    <visual><origin xyz="0 0 1.3"/><geometry><box size="0.2 0.2 0.2"/></geometry><material name="skin"/></visual>
    <collision><origin xyz="0 0 1.3"/><geometry><box size="0.2 0.2 0.2"/></geometry></collision>
  </link>
  <joint name="neck_joint" type="revolute">
    <parent link="torso_link"/><child link="head_link"/><origin xyz="0 0 0.9"/><axis xyz="0 1 0"/><limit lower="-0.5" upper="0.5" effort="5" velocity="1.0"/>
  </joint>

  <!-- Right Arm -->
  <link name="upper_arm_r">
    <visual><origin xyz="0 -0.325 0.85"/><geometry><box size="0.1 0.1 0.3"/></geometry><material name="skin"/></visual>
    <collision><origin xyz="0 -0.325 0.85"/><geometry><box size="0.1 0.1 0.3"/></geometry></collision>
  </link>
  <joint name="shoulder_joint_r" type="revolute">
    <parent link="torso_link"/><child link="upper_arm_r"/><origin xyz="0 -0.2 0.85"/><axis xyz="0 1 0"/><limit lower="-1.5" upper="1.5" effort="10" velocity="1.0"/>
  </joint>

  <link name="lower_arm_r">
    <visual><origin xyz="0 -0.325 0.55"/><geometry><box size="0.1 0.1 0.3"/></geometry><material name="skin"/></visual>
    <collision><origin xyz="0 -0.325 0.55"/><geometry><box size="0.1 0.1 0.3"/></geometry></collision>
  </link>
  <joint name="elbow_joint_r" type="revolute">
    <parent link="upper_arm_r"/><child link="lower_arm_r"/><origin xyz="0 -0.325 0.7"/><axis xyz="1 0 0"/><limit lower="0" upper="1.5" effort="10" velocity="1.0"/>
  </joint>

  <!-- Left Arm -->
  <link name="upper_arm_l">
    <visual><origin xyz="0 0.325 0.85"/><geometry><box size="0.1 0.1 0.3"/></geometry><material name="skin"/></visual>
    <collision><origin xyz="0 0.325 0.85"/><geometry><box size="0.1 0.1 0.3"/></geometry></collision>
  </link>
  <joint name="shoulder_joint_l" type="revolute">
    <parent link="torso_link"/><child link="upper_arm_l"/><origin xyz="0 0.2 0.85"/><axis xyz="0 1 0"/><limit lower="-1.5" upper="1.5" effort="10" velocity="1.0"/></joint>

  <link name="lower_arm_l">
    <visual><origin xyz="0 0.325 0.55"/><geometry><box size="0.1 0.1 0.3"/></geometry><material name="skin"/></visual>
    <collision><origin xyz="0 0.325 0.55"/><geometry><box size="0.1 0.1 0.3"/></geometry></collision>
  </link>
  <joint name="elbow_joint_l" type="revolute">
    <parent link="upper_arm_l"/><child link="lower_arm_l"/><origin xyz="0 0.325 0.7"/><axis xyz="1 0 0"/><limit lower="0" upper="1.5" effort="10" velocity="1.0"/>
  </joint>

</robot> 